Workbook

Sheet As Values
N2: Mister Kiosk Stickers (KSS) | T2: Gen 2 Peg KSS | AB2: Gen 1 Peg KSS | AE2: DRB KSS | AN2: Awareness Flyers | BG2: Handheld Menus | BZ2: 28x44 Windscreens | CG2: Roadside Banners | CN2: Scancards | CP2: V | CQ2: V | CT2: Collateral Guide | DB2: Box Sticker
A3: NEW BUILD BLITZ WAVE 4 August 2026 | E3: Last updated | F3: 46244 | M3: Filename | N3: NB Blitz 4-UWC-KSS-Mister-V4-10F-101-Print.pdf | O3: NB Blitz 4-UWC-KSS-Mister-V4-8F-304-Print.pdf | P3: NB Blitz 4-UWC-KSS-Mister-V4-A-01-Print.pdf | Q3: NB Blitz 4-UWC-KSS-Mister-V4-B-06-Print.pdf | R3: NB Blitz 4-UWC-KSS-Mister-V4-D-01-Print.pdf | S3: NB Blitz 4-UWC-KSS-Mister-V4-E-01-Print.pdf | T3: 2026 09 Promo-NB Blitz 4-UWC-KSS-Peg2-A-01-Print.pdf | U3: 2026 09 Promo-NB Blitz 4-UWC-KSS-Peg2-B-01-Print.pdf | V3: 2026 09 Promo-NB Blitz 4-UWC-KSS-Peg2-C-01-Print.pdf | W3: 2026 09 Promo-NB Blitz 4-UWC-KSS-Peg2-D-01-Print.pdf | X3: 2026 09 Promo-NB Blitz 4-UWC-KSS-Peg2 8D-04-Print.pdf | Y3: 2026 09 Promo-NB Blitz 4-UWC-KSS-Peg2-E-01-Print.pdf | Z3: 2026 09 Promo-NB Blitz 4-UWC-KSS-Peg2-8F-304-Print.pdf | AA3: 2026 09 Promo-NB Blitz 4-UWC-KSS-Peg2-10F-101-Print.pdf | AB3: 2026 09 Promo-NB Blitz 4-UWC-KSS-Peg1 10F-201-Print.pdf | AC3: 2026 09 Promo-NB Blitz 4-UWC-KSS-Peg1-D-01-Print.pdf | AD3: 2026 09 Promo-NB Blitz 4-UWC-KSS-Peg1-B-01-Print.pdf | AE3: 2026 09 Promo-NB Blitz 4-UWC-KSS-DRB XPT 2012-A-01-Print.pdf | AF3: 2026 09 Promo-NB Blitz 4-UWC-KSS-DRB XPT 2012-B-01-Print.pdf | AG3: 2026 09 Promo-NB Blitz 4-UWC-KSS-DRB XPT 2012-C-01-Print.pdf | AH3: 2026 09 Promo-NB Blitz 4-UWC-KSS-DRB XPT 2012-D-01-Print.pdf | AI3: 2026 09 Promo-NB Blitz 4-UWC-KSS-DRB XPT 2012 8D-05-Print.pdf | AJ3: 2026 09 Promo-NB Blitz 4-UWC-KSS-DRB XPT 2012-E-01-Print.pdf | AK3: 2026 09 Promo-NB Blitz 4-UWC-KSS-DRB XPT 2012-8F-304-Print.pdf | AL3: 2026 09 Promo-NB Blitz 4-UWC-KSS-DRB XPT 2012-10F-101-Print.pdf | AM3: 2026 09 Promo-NB Blitz 4-UWC-KSS-DRB XPT 2012-E-01-Print.pdf | AN3: 2026 09 Promo-NB Blitz 4-POR-1mo-UWC-Awareness-10-10F-101-Print.pdf | AO3: 2026 09 Promo-NB Blitz 4-POR-1mo-UWC-Awareness-10-10F-104-Print.pdf | AP3: 2026 09 Promo-NB Blitz 4-POR-1mo-UWC-Awareness-10-10F-201-Print.pdf | AQ3: 2026 09 Promo-NB Blitz 4-999-1mo-UWC-Awareness-8D-04-Print.pdf | AR3: 2026 09 Promo-NB Blitz 4-999-1mo-UWC-Awareness-8D-05-Print.pdf | AS3: 2026 09 Promo-NB Blitz 4-POR-1mo-UWC-Awareness-8-8F-304-Print.pdf | AT3: 2026 09 Promo-NB Blitz 4-10-3mos-UWC-Awareness-A-01-Print.pdf | AU3: 2026 09 Promo-NB Blitz 4-15 off-1mo-UWC-Awareness-B-01-Print.pdf | AV3: 2026 09 Promo-NB Blitz 4-15 off-1mo-UWC-Awareness-B-05-Print.pdf | AW3: 2026 09 Promo-NB Blitz 4-15 off-1mo-UWC-Awareness-B-06-Print.pdf | AX3: 2026 09 Promo-NB Blitz 4-5 10 15-1mo-UWC-Awareness-V2-C-01-Print.pdf | AY3: 2026 09 Promo-NB Blitz 4-5 10 15-1mo-UWC-Awareness-V2-C-04-Print.pdf | AZ3: 2026 09 Promo-NB Blitz 4-999-1mo-UWC-Awareness-D-01-Print.pdf | BA3: 2026 09 Promo-NB Blitz 4-999-1mo-UWC-Awareness-D-02-Print.pdf | BB3: 2026 09 Promo-NB Blitz 4-999-1mo-UWC-Awareness-D-03-Print.pdf | BC3: 2026 09 Promo-NB Blitz 4-999-1mo-UWC-Awareness-D-06-Print.pdf | BD3: 2026 09 Promo-NB Blitz 4-50 off-1mo-UWC-Awareness-E-01-Print.pdf | BE3: 2026 09 Promo-NB Blitz 4-50 off-1mo-UWC-Awareness-E-03-Print.pdf | BF3: 2026 09 Promo-NB Blitz 4-50 off-1mo-UWC-Awareness-E-07-Print.pdf | BG3: 2026 09 Promo-NB Blitz 4-POR-1mo-HandheldMenu-10-10F-101-Print.pdf | BH3: 2026 09 Promo-NB Blitz 4-POR-1mo-HandheldMenu-10-10F-104-Print.pdf | BI3: 2026 09 Promo-NB Blitz 4-POR-1mo-HandheldMenu-10-10F-201-Print.pdf | BJ3: 2026 09 Promo-NB Blitz 4-999-1mo-HandheldMenu-8D-04-Print.pdf | BK3: 2026 09 Promo-NB Blitz 4-999-1mo-HandheldMenu-8D-05-Print.pdf | BL3: 2026 09 Promo-NB Blitz 4-POR-1mo-HandheldMenu-8-8F-304-Print.pdf | BM3: 2026 09 Promo-NB Blitz 4-10-3mos-HandheldMenu-A-01-Print.pdf | BN3: 2026 09 Promo-NB Blitz 4-15 off-1mo-HandheldMenu-B-01-Print.pdf | BO3: 2026 09 Promo-NB Blitz 4-15 off-1mo-HandheldMenu-B-05-Print.pdf | BP3: 2026 09 Promo-NB Blitz 4-15 off-1mo-HandheldMenu-B-06-Print.pdf | BQ3: 2026 09 Promo-NB Blitz 4-5 10 15-1mo-HandheldMenu-V2-C-01-Print.pdf | BR3: 2026 09 Promo-NB Blitz 4-5 10 15-1mo-HandheldMenu-V2-C-04-Print.pdf | BS3: 2026 09 Promo-NB Blitz 4-999-1mo-HandheldMenu-D-01-Print.pdf | BT3: 2026 09 Promo-NB Blitz 4-999-1mo-HandheldMenu-D-02-Print.pdf | BU3: 2026 09 Promo-NB Blitz 4-999-1mo-HandheldMenu-D-03-Print.pdf | BV3: 2026 09 Promo-NB Blitz 4-999-1mo-HandheldMenu-D-06-Print.pdf | BW3: 2026 09 Promo-NB Blitz 4-50 off-1mo-HandheldMenu-E-01-Print.pdf | BX3: 2026 09 Promo-NB Blitz 4-50 off-1mo-HandheldMenu-E-03-Print.pdf | BY3: 2026 09 Promo-NB Blitz 4-50 off-1mo-HandheldMenu-E-07-Print.pdf | BZ3: 2026 09 Promo-NB Blitz 4-UWC-WS-28x44-A-Print.pdf | CA3: 2026 09 Promo-NB Blitz 4-UWC-WS-28x44-B-Print.pdf | CB3: 2026 09 Promo-NB Blitz 4-UWC-WS-28x44-D-Print.pdf | CC3: 2026 09 Promo-NB Blitz 4-UWC-WS-28x44-8D-Print.pdf | CD3: 2026 09 Promo-NB Blitz 4-UWC-WS-28x44-E-Print.pdf | CE3: 2026 09 Promo-NB Blitz 4-UWC-WS-28x44-8F-Print.pdf | CF3: 2026 09 Promo-NB Blitz 4-UWC-WS-28x44-10F-Print.pdf | CG3: 2026 09 Promo-UWC-96x36 Banner-V4-A-Print.pdf | CH3: 2026 09 Promo-UWC-96x36 Banner-V4-B-Print.pdf | CI3: 2026 09 Promo-UWC-96x36 Banner-V4-C-Print.pdf | CJ3: 2026 09 Promo-UWC-96x36 Banner-V4-D-Print.pdf | CK3: 2026 09 Promo-UWC-96x36 Banner-V4-E-Print.pdf | CL3: 2026 09 Promo-UWC-96x36 Banner-V4-8F-Print.pdf | CM3: 2026 09 Promo-UWC-96x36 Banner-V4-10F-Print.pdf | CN3: 2026 09 Promo 10off 3mos Scan Cards-V2-Print | CO3: 2026 09 Promo-15 Off-1mo-ScanCard-Print | CP3: 2026 09 Promo-5-10-15-1mo-ScanCardSet-Print | CQ3: 2026 09 Promo-999-1mo-ScanCardSet-Print.pdf | CR3: 2026 09 Promo-50off-1mo-ScanCard-Print.pdf | CS3: 2026 09 All Plans PoR 1mo Scan Cards-V2-Print.pdf | CT3: 2026 09 Promo-NB Blitz 4-Collateral Guides-A-Print.pdf | CU3: 2026 09 Promo-NB Blitz 4-Collateral Guides-B-Print.pdf | CV3: 2026 09 Promo-NB Blitz 4-Collateral Guides-C-Print.pdf | CW3: 2026 09 Promo-NB Blitz 4-Collateral Guides-8D-Print.pdf | CX3: 2026 09 Promo-NB Blitz 4-Collateral Guides-D-Print.pdf | CY3: 2026 09 Promo-NB Blitz 4-Collateral Guides-E-Print.pdf | CZ3: 2026 09 Promo-NB Blitz 4-Collateral Guides-8F-Print.pdf | DA3: 2026 09 Promo-NB Blitz 4-Collateral Guides-10F-Print.pdf | DB3: Box Sticker
A4: Region | B4: CC | C4: Store # | D4: Vlookup Store # | E4: Location Name | F4: General Manager | G4: Address | H4: City | I4: State | J4: Zip Code | K4: Phone Number | L4: Promo | M4: Art Code | N4: 10F | O4: 8F | P4: A | Q4: B | R4: D | S4: E | T4: A | U4: B | V4: C | W4: D | X4: 8D | Y4: E | Z4: 8F | AA4: 10F | AB4: 10F | AC4: D | AD4: B | AE4: A | AF4: B | AG4: C | AH4: D | AI4: 8D | AJ4: E | AK4: 8F | AL4: 10F | AM4: E | AN4: 10F-101 | AO4: 10F-104 | AP4: 10F-201 | AQ4: 8D-04 | AR4: 8D-05 | AS4: 8F-304 | AT4: A01 | AU4: B01 | AV4: B05 | AW4: B06 | AX4: C01 | AY4: C04 | AZ4: D01 | BA4: D02 | BB4: D03 | BC4: D06 | BD4: E01 | BE4: E03 | BF4: E07 | BG4: 10F-101 | BH4: 10F-104 | BI4: 10F-201 | BJ4: 8D-04 | BK4: 8D-05 | BL4: 8F-304 | BM4: A01 | BN4: B01 | BO4: B05 | BP4: B06 | BQ4: C01 | BR4: C04 | BS4: D01 | BT4: D02 | BU4: D03 | BV4: D06 | BW4: E01 | BX4: E03 | BY4: E07 | BZ4: A | CA4: B | CB4: D | CC4: 8D | CD4: E | CE4: 8F | CF4: 10F | CG4: A | CH4: B | CI4: C | CJ4: D | CK4: E | CL4: 8F | CM4: 10F | CN4: A5 | CO4: B7 | CP4: C8 | CQ4: D9 | CR4: E12 | CS4: F | CT4: A | CU4: B | CV4: C | CW4: 8D | CX4: D | CY4: E | CZ4: 8F | DA4: 10F
A5: AL-Huntsville | B5: 813 | C5: 0041 | D5: 41 | E5: Hartselle | F5: MaryGrace Gilley | G5: 1206 HIGHWAY 31 NW | H5: HARTSELLE | I5: AL | J5: 35640-4421 | K5: (256) 773-7737 | L5: 50% off all plan 1 mo. | M5: E01 | AJ5: 1 | BD5: 1500 | BW5: 10 | CK5: 2 | CR5: 10 | CX5: 1 | DB5: 1
A6: AL-Huntsville | B6: 813 | C6: 0042 | D6: 42 | E6: Limestone | F6: Jamie Garrie | G6: 1321 US HIGHWAY 72 E | H6: ATHENS | I6: AL | J6: 35611-4405 | K6: (256) 233-2290 | L6: 50% off all plan 1 mo. | M6: E01 | AJ6: 1 | BD6: 1500 | BW6: 10 | CK6: 2 | CR6: 10 | CX6: 1 | DB6: 1
A7: AL-Huntsville | B7: 813 | C7: 0043 | D7: 43 | E7: Madison | F7: Klaryssa Melendrez | G7: 5509 PROMENADE POINT PKWY | H7: MADISON | I7: AL | J7: 35758-6701 | K7: (256) 895-2693 | L7: 50% off all plan 1 mo. | M7: E01 | AJ7: 1 | BD7: 1500 | BW7: 10 | CK7: 2 | CR7: 10 | CX7: 1 | DB7: 1
A8: AL-Huntsville | B8: 813 | C8: 0044 | D8: 44 | E8: Setter | F8: Stevie Wagner | G8: 627 BELTLINE RD SW | H8: DECATUR | I8: AL | J8: 35601 | K8: (256) 867-0108 | L8: 50% off all plan 1 mo. | M8: E01 | AJ8: 1 | BD8: 1500 | BW8: 10 | CK8: 2 | CR8: 10 | CX8: 1 | DB8: 1
A9: AL-Huntsville | B9: 813 | C9: 0045 | D9: 45 | E9: 9th Street | F9: Christian Rider | G9: 2240 BELTLINE RD SW | H9: DECATUR | I9: AL | J9: 35601-7001 | K9: (256) 822-2939 | L9: 50% off all plan 1 mo. | M9: E01 | AJ9: 1 | BD9: 1500 | BW9: 10 | CK9: 2 | CR9: 10 | CX9: 1 | DB9: 1
A10: AL-Huntsville | B10: 813 | C10: 0046 | D10: 46 | E10: Bassett Ave | F10: Josh Lamey | G10: 721 14TH ST SE | H10: DECATUR | I10: AL | J10: 35601-5911 | K10: (256) 822-2029 | L10: 50% off all plan 1 mo. | M10: E01 | AJ10: 1 | BD10: 1500 | BW10: 10 | CK10: 2 | CR10: 10 | CX10: 1 | DB10: 1
A11: AL-Huntsville | B11: 813 | C11: 0047 | D11: 47 | E11: Grace | F11: Justin Williams | G11: 403 US HIGHWAY 72 W | H11: ATHENS | I11: AL | J11: 35611-4207 | K11: (256) 998-5312 | L11: 50% off all plan 1 mo. | M11: E01 | AJ11: 1 | BD11: 1500 | BW11: 10 | CK11: 2 | CR11: 10 | CX11: 1 | DB11: 1
A12: AL-Huntsville | B12: 813 | C12: 0051 | D12: 51 | E12: Azalea | F12: Colby Gray | G12: 271 AZALEA DR | H12: FLORENCE | I12: AL | J12: 35630-1733 | K12: (256) 766-2726 | L12: 50% off all plan 1 mo. | M12: E01 | AJ12: 1 | BD12: 1500 | BW12: 10 | CK12: 2 | CR12: 10 | CX12: 1 | DB12: 1
A13: AL-Huntsville | B13: 813 | C13: 0052 | D13: 52 | E13: Muscle Shoals | F13: Olivia Thomsen | G13: 702 AVALON AVE | H13: MUSCLE SHOALS | I13: AL | J13: 35661-2304 | K13: (256) 389-3890 | L13: 50% off all plan 1 mo. | M13: E01 | BD13: 1500 | BW13: 10 | CD13: 1 | CK13: 2 | CR13: 10 | CX13: 1 | DB13: 1
A14: AL-Huntsville | B14: 813 | C14: 0053 | D14: 53 | E14: Cloverdale | F14: Katherine Huddleston | G14: 2914 CLOVERDALE RD | H14: FLORENCE | I14: AL | J14: 35633 | K14: (256) 712-0183 | L14: 50% off all plan 1 mo. | M14: E01 | AJ14: 1 | BD14: 1500 | BW14: 10 | CK14: 2 | CR14: 10 | CX14: 1 | DB14: 1
A15: AZ-Tucson | B15: 806 | C15: 0326 | D15: 326 | E15: Swan | F15: Sierrah Bainter | G15: 4600 E BROADWAY BLVD | H15: TUCSON | I15: AZ | J15: 85711-3512 | K15: (520) 428-0256 | L15: $9.99 all plans 1 mo. | M15: D01 | AZ15: 1500 | BS15: 10 | CB15: 1 | CJ15: 2 | CQ15: 10 | CX15: 1 | DB15: 1
A16: AZ-Tucson | B16: 806 | C16: 0327 | D16: 327 | E16: South Kolb | F16: Evelyn Conger | G16: 2409 S KOLB RD | H16: TUCSON | I16: AZ | J16: 85710 | K16: (520) 721-9290 | L16: $9.99 all plans 1 mo. | M16: D01 | AZ16: 1500 | BS16: 10 | CB16: 1 | CJ16: 2 | CQ16: 10 | CX16: 1 | DB16: 1
A17: AZ-Tucson | B17: 806 | C17: 0328 | D17: 328 | E17: Euclid | F17: Stefanie Osuna | G17: 730 E BROADWAY BLVD | H17: TUCSON | I17: AZ | J17: 85719 | K17: (520) 623-2923 | L17: $9.99 all plans 1 mo. | M17: D01 | AZ17: 1500 | BS17: 10 | CB17: 1 | CJ17: 2 | CQ17: 10 | CX17: 1 | DB17: 1
A18: AZ-Tucson | B18: 806 | C18: 0335 | D18: 335 | E18: E Grant | F18: 0 | G18: 3150 E GRANT RD | H18: TUCSON | I18: AZ | J18: 85716 | K18: (520) 881-1486 | L18: $9.99 all plans 1 mo. | M18: D01 | AZ18: 1500 | BS18: 10 | CB18: 1 | CJ18: 2 | CQ18: 10 | CX18: 1 | DB18: 1
A19: AZ-Tucson | B19: 806 | C19: 1329 | D19: 1329 | E19: Craycroft | F19: Chandrani Das | G19: 5515 E GRANT RD | H19: TUCSON | I19: AZ | J19: 85712 | K19: (520) 497-1922 | L19: $9.99 all plans 1 mo. | M19: D01 | R19: 2 | AZ19: 1500 | BS19: 10 | CJ19: 2 | CQ19: 10 | CX19: 1 | DB19: 1
A20: AZ-Tucson | B20: 806 | C20: 1331 | D20: 1331 | E20: Twin Peaks | F20: Vanna Valdez | G20: 6520 W MARANA CENTER BL | H20: TUCSON | I20: AZ | J20: 85742 | K20: (520) 335-8707 | L20: $9.99 all plans 1 mo. | M20: D01 | R20: 1 | AZ20: 1500 | BS20: 10 | CJ20: 2 | CQ20: 10 | CX20: 1 | DB20: 1
A21: AZ-Tucson | B21: 806 | C21: 2552 | D21: 2552 | E21: Tucson Mall | F21: Natalie Vazquez Martinez | G21: 4646 N ORACLE | H21: TUCSON | I21: AZ | J21: 85705 | K21: (520) 485-2620 | L21: $9.99 all plans 1 mo. | M21: D01 | R21: 1 | AZ21: 1500 | BS21: 10 | CJ21: 2 | CQ21: 10 | CX21: 1 | DB21: 1
A22: AZ-Tucson | B22: 806 | C22: 2557 | D22: 2557 | E22: Cardinal | F22: Martin Soto | G22: 2850 W VALENCIA ROAD | H22: TUCSON | I22: AZ | J22: 85746 | K22: (520) 497-1992 | L22: $9.99 all plans 1 mo. | M22: D01 | R22: 1 | AZ22: 1500 | BS22: 10 | CJ22: 2 | CQ22: 10 | CX22: 1 | DB22: 1
A23: CA-Bakersfield | B23: 830 | C23: 1016 | D23: 1016 | E23: Rosedale Hwy | F23: Adrian Vargas | G23: 11921 ROSEDALE HIGHWAY | H23: BAKERSFIELD | I23: CA | J23: 93312 | K23: (661) 230-5335 | L23: $9.99 all plans 1 mo. | M23: D01 | W23: 2 | AZ23: 1500 | BS23: 10 | CJ23: 2 | CQ23: 10 | CX23: 1 | DB23: 1
A24: CA-Bakersfield | B24: 830 | C24: 1034 | D24: 1034 | E24: Carmen | F24: Edgar Barron | G24: 1925 S BROADWAY | H24: SANTA MARIA | I24: CA | J24: 93454 | K24: (805) 621-6835 | L24: $9.99 all plans 1 mo. | M24: D01 | R24: 2 | AZ24: 1500 | BS24: 10 | CJ24: 2 | CQ24: 10 | CX24: 1 | DB24: 1
A25: CA-Bakersfield | B25: 830 | C25: 1035 | D25: 1035 | E25: Hosking | F25: Susana Ledina | G25: 1601 HOSKING AVE | H25: BAKERSFIELD | I25: CA | J25: 93307 | K25: (661) 336-9952 | L25: $9.99 all plans 1 mo. | M25: D01 | R25: 1 | AZ25: 1500 | BS25: 10 | CJ25: 2 | CQ25: 10 | CX25: 1 | DB25: 1
A26: CA-Bakersfield | B26: 830 | C26: 1038 | D26: 1038 | E26: Heath | F26: Hailey Divina | G26: 16214 STOCKDALE HWY | H26: BAKERSFIELD | I26: CA | J26: 93314 | K26: (661) 336-9403 | L26: $9.99 all plans 1 mo. | M26: D01 | R26: 2 | AZ26: 1500 | BS26: 10 | CJ26: 2 | CQ26: 10 | CX26: 1 | DB26: 1
A27: CA-Bakersfield | B27: 830 | C27: 1058 | D27: 1058 | E27: Stockdale | F27: Jorge Escobar | G27: 11417 STOCKDALE HWY | H27: BAKERSFIELD | I27: CA | J27: 93311 | K27: (661) 636-6520 | L27: $9.99 all plans 1 mo. | M27: D01 | R27: 2 | AZ27: 1500 | BS27: 10 | CJ27: 2 | CQ27: 10 | CX27: 1 | DB27: 1
A28: CA-Los Angeles | B28: 830 | C28: 1013 | D28: 1013 | E28: Hwy 138 | F28: Kayla Lopez | G28: 1822 E PALMDALE BLVD | H28: PALMDALE | I28: CA | J28: 93550 | K28: (661) 268-6424 | L28: $9.99 all plans 1 mo. | M28: D01 | W28: 2 | AZ28: 1500 | BS28: 10 | CJ28: 2 | CQ28: 10 | CX28: 1 | DB28: 1
A29: CA-Los Angeles | B29: 830 | C29: 1018 | D29: 1018 | E29: Rialto | F29: Olivia Rodriguez | G29: 127 WEST VALLEY BLVD | H29: RIALTO | I29: CA | J29: 92376 | K29: (909) 237-8099 | L29: $9.99 all plans 1 mo. | M29: D01 | R29: 2 | AZ29: 1500 | BS29: 10 | CJ29: 2 | CQ29: 10 | CX29: 1 | DB29: 1
A30: CA-Los Angeles | B30: 830 | C30: 1027 | D30: 1027 | E30: Stoneridge | F30: Zachary Ojeda | G30: 27240 EUCALYPTUS AVE | H30: MORENO VALLEY | I30: CA | J30: 92555 | K30: (951) 221-3009 | L30: $9.99 all plans 1 mo. | M30: D01 | R30: 2 | AZ30: 1500 | BS30: 10 | CJ30: 2 | CQ30: 10 | CX30: 1 | DB30: 1
A31: CA-Los Angeles | B31: 830 | C31: 1037 | D31: 1037 | E31: Varsity | F31: Anthony Fickewirth | G31: 4212 N VARSITY AVE | H31: SAN BERNARDINO | I31: CA | J31: 92407 | K31: (909) 277-6601 | L31: $9.99 all plans 1 mo. | M31: D01 | R31: 2 | AZ31: 1500 | BS31: 10 | CJ31: 2 | CQ31: 10 | CX31: 1 | DB31: 1
A32: CA-Modesto | B32: 831 | C32: 0915 | D32: 915 | E32: Merced | F32: Manuel Toro Garcia | G32: 1800 WEST OLIVE AVE | H32: MERCED | I32: CA | J32: 95348 | K32: (209) 388-9274 | L32: $9.99 all plans 1 mo. | M32: D01 | W32: 1 | AZ32: 1500 | BS32: 10 | CJ32: 2 | CQ32: 10 | CX32: 1 | DB32: 1
A33: CA-Modesto | B33: 830 | C33: 1076 | D33: 1076 | E33: Tuolumne | F33: Elicia Solis | G33: 2530 COUNTRYSIDE DR | H33: TURLOCK | I33: CA | J33: 95380 | K33: (350) 203-2119 | L33: $9.99 all plans 1 mo. | M33: D01 | R33: 2 | AZ33: 1500 | BS33: 10 | CJ33: 2 | CQ33: 10 | CX33: 1 | DB33: 1
A34: CA-San Joaquin Valley | B34: 830 | C34: 1039 | D34: 1039 | E34: Mooney Blvd | F34: Maurice Lacy | G34: 1920 S MOONEY BLVD | H34: VISALIA | I34: CA | J34: 93277 | K34: (559) 372-0454 | L34: All Plans PoR 1 mo. | M34: 10F-101 | N34: 2 | AN34: 1500 | BG34: 10 | CM34: 2 | CS34: 10 | DA34: 1 | DB34: 1
A35: CA-San Joaquin Valley | B35: 830 | C35: 1072 | D35: 1072 | E35: Reedley | F35: Francisco Villatoro | G35: 1595 W MANNING AVE | H35: REEDLEY | I35: CA | J35: 93654 | K35: (559) 554-1641 | L35: All Plans PoR 1 mo. | M35: 10F-101 | N35: 2 | AN35: 1500 | BG35: 10 | CM35: 2 | CS35: 10 | DA35: 1 | DB35: 1
A36: CA-Victor Valley | B36: 830 | C36: 1019 | D36: 1019 | E36: Happy Trails Hwy | F36: Salvador Ramirez | G36: 20440 OUTER HWY 18 | H36: APPLE VALLEY | I36: CA | J36: 92307 | K36: (760) 503-0311 | L36: $9.99 all plans 1 mo. | M36: D01 | R36: 1 | AZ36: 1500 | BS36: 10 | CJ36: 2 | CQ36: 10 | CX36: 1 | DB36: 1
A37: CA-Victor Valley | B37: 830 | C37: 1031 | D37: 1031 | E37: Jellico Ave | F37: Kenyon Mcwhorter | G37: 17112 MAIN STREET | H37: HESPERIA | I37: CA | J37: 92345 | K37: (442) 267-6146 | L37: $9.99 all plans 1 mo. | M37: D01 | R37: 2 | AZ37: 1500 | BS37: 10 | CJ37: 2 | CQ37: 10 | CX37: 1 | DB37: 1
A38: CA-Victor Valley | B38: 830 | C38: 1064 | D38: 1064 | E38: Bear Valley | F38: Natalie Craven | G38: 19389 BEAR VALLEY RD | H38: APPLE VALLEY | I38: CA | J38: 92308 | K38: (442) 855-7229 | L38: $9.99 all plans 1 mo. | M38: D01 | R38: 1 | AZ38: 1500 | BS38: 10 | CJ38: 2 | CQ38: 10 | CX38: 1 | DB38: 1
A39: CO-Colorado Springs/Pueblo/Denver | B39: 810 | C39: 0341 | D39: 341 | E39: Prospect Ave | F39: Davante Jordan | G39: 24273 E PROSPECT AVE | H39: AURORA | I39: CO | J39: 80016 | K39: (303) 928-7520 | L39: $15 off all plans 1 mo. | M39: B06 | AW39: 1500 | BP39: 10 | CA39: 1 | CH39: 2 | CO39: 10 | CU39: 1 | DB39: 1
A40: CO-Colorado Springs/Pueblo/Denver | B40: 810 | C40: 0343 | D40: 343 | E40: Woodmen | F40: Marvin Willis | G40: 5366 NEW CAR DR | H40: COLORADO SPRINGS | I40: CO | J40: 80923-8854 | K40: (719) 266-0169 | L40: $15 off all plans 1 mo. | M40: B05 | Q40: 2 | AV40: 1500 | BO40: 10 | CH40: 2 | CO40: 10 | CU40: 1 | DB40: 1
A41: CO-Colorado Springs/Pueblo/Denver | B41: 810 | C41: 0344 | D41: 344 | E41: Bradley | F41: Michael Dye | G41: 1822 MAIN ST | H41: COLORADO SPRINGS | I41: CO | J41: 80911-1152 | K41: (719) 392-2250 | L41: $15 off all plans 1 mo. | M41: B05 | Q41: 1 | AV41: 1500 | BO41: 10 | CH41: 2 | CO41: 10 | CU41: 1 | DB41: 1
...

Sheet As Values Modified
N1: 1 | O1: 1 | P1: 1 | Q1: 1 | R1: 1 | S1: 1 | T1: 1 | U1: 1 | V1: 1 | W1: 1 | X1: 1 | Y1: 1 | Z1: 1 | AA1: 1 | AB1: 1 | AC1: 1 | AD1: 1 | AE1: 1 | AF1: 1 | AG1: 1 | AH1: 1 | AI1: 1 | AJ1: 1 | AK1: 1 | AL1: 1 | AM1: 1 | AN1: 2 | AO1: 2 | AP1: 2 | AQ1: 2 | AR1: 2 | AS1: 2 | AT1: 2 | AU1: 2 | AV1: 2 | AW1: 2 | AX1: 2 | AY1: 2 | AZ1: 2 | BA1: 2 | BB1: 2 | BC1: 2 | BD1: 2 | BE1: 2 | BF1: 2 | BG1: 2 | BH1: 2 | BI1: 2 | BJ1: 2 | BK1: 2 | BL1: 2 | BM1: 2 | BN1: 2 | BO1: 2 | BP1: 2 | BQ1: 2 | BR1: 2 | BS1: 2 | BT1: 2 | BU1: 2 | BV1: 2 | BW1: 2 | BX1: 2 | BY1: 2 | BZ1: 3 | CA1: 3 | CB1: 3 | CC1: 3 | CD1: 3 | CE1: 3 | CF1: 3 | CG1: 1 | CH1: 1 | CI1: 1 | CJ1: 1 | CK1: 1 | CL1: 1 | CM1: 1 | CN1: 2 | CO1: 2 | CP1: 2 | CQ1: 2 | CR1: 2 | CS1: 2 | CT1: 2 | CU1: 2 | CV1: 2 | CW1: 2 | CX1: 2 | CY1: 2 | CZ1: 2 | DA1: 2
N2: Mister Kiosk Stickers (KSS) | T2: Gen 2 Peg KSS | AB2: Gen 1 Peg KSS | AE2: DRB KSS | AN2: Awareness Flyers | BG2: Handheld Menus | BZ2: 28x44 Windscreens | CG2: Roadside Banners | CN2: Scancards | CP2: V | CQ2: V | CT2: Collateral Guide | DB2: Box Sticker
A3: NEW BUILD BLITZ WAVE 4 August 2026 | E3: Last updated | F3: 46244 | M3: Filename | N3: NB Blitz 4-UWC-KSS-Mister-V4-10F-101-Print.pdf | O3: NB Blitz 4-UWC-KSS-Mister-V4-8F-304-Print.pdf | P3: NB Blitz 4-UWC-KSS-Mister-V4-A-01-Print.pdf | Q3: NB Blitz 4-UWC-KSS-Mister-V4-B-06-Print.pdf | R3: NB Blitz 4-UWC-KSS-Mister-V4-D-01-Print.pdf | S3: NB Blitz 4-UWC-KSS-Mister-V4-E-01-Print.pdf | T3: 2026 09 Promo-NB Blitz 4-UWC-KSS-Peg2-A-01-Print.pdf | U3: 2026 09 Promo-NB Blitz 4-UWC-KSS-Peg2-B-01-Print.pdf | V3: 2026 09 Promo-NB Blitz 4-UWC-KSS-Peg2-C-01-Print.pdf | W3: 2026 09 Promo-NB Blitz 4-UWC-KSS-Peg2-D-01-Print.pdf | X3: 2026 09 Promo-NB Blitz 4-UWC-KSS-Peg2 8D-04-Print.pdf | Y3: 2026 09 Promo-NB Blitz 4-UWC-KSS-Peg2-E-01-Print.pdf | Z3: 2026 09 Promo-NB Blitz 4-UWC-KSS-Peg2-8F-304-Print.pdf | AA3: 2026 09 Promo-NB Blitz 4-UWC-KSS-Peg2-10F-101-Print.pdf | AB3: 2026 09 Promo-NB Blitz 4-UWC-KSS-Peg1 10F-201-Print.pdf | AC3: 2026 09 Promo-NB Blitz 4-UWC-KSS-Peg1-D-01-Print.pdf | AD3: 2026 09 Promo-NB Blitz 4-UWC-KSS-Peg1-B-01-Print.pdf | AE3: 2026 09 Promo-NB Blitz 4-UWC-KSS-DRB XPT 2012-A-01-Print.pdf | AF3: 2026 09 Promo-NB Blitz 4-UWC-KSS-DRB XPT 2012-B-01-Print.pdf | AG3: 2026 09 Promo-NB Blitz 4-UWC-KSS-DRB XPT 2012-C-01-Print.pdf | AH3: 2026 09 Promo-NB Blitz 4-UWC-KSS-DRB XPT 2012-D-01-Print.pdf | AI3: 2026 09 Promo-NB Blitz 4-UWC-KSS-DRB XPT 2012 8D-05-Print.pdf | AJ3: 2026 09 Promo-NB Blitz 4-UWC-KSS-DRB XPT 2012-E-01-Print.pdf | AK3: 2026 09 Promo-NB Blitz 4-UWC-KSS-DRB XPT 2012-8F-304-Print.pdf | AL3: 2026 09 Promo-NB Blitz 4-UWC-KSS-DRB XPT 2012-10F-101-Print.pdf | AM3: 2026 09 Promo-NB Blitz 4-UWC-KSS-DRB XPT 2012-E-01-Print.pdf | AN3: 2026 09 Promo-NB Blitz 4-POR-1mo-UWC-Awareness-10-10F-101-Print.pdf | AO3: 2026 09 Promo-NB Blitz 4-POR-1mo-UWC-Awareness-10-10F-104-Print.pdf | AP3: 2026 09 Promo-NB Blitz 4-POR-1mo-UWC-Awareness-10-10F-201-Print.pdf | AQ3: 2026 09 Promo-NB Blitz 4-999-1mo-UWC-Awareness-8D-04-Print.pdf | AR3: 2026 09 Promo-NB Blitz 4-999-1mo-UWC-Awareness-8D-05-Print.pdf | AS3: 2026 09 Promo-NB Blitz 4-POR-1mo-UWC-Awareness-8-8F-304-Print.pdf | AT3: 2026 09 Promo-NB Blitz 4-10-3mos-UWC-Awareness-A-01-Print.pdf | AU3: 2026 09 Promo-NB Blitz 4-15 off-1mo-UWC-Awareness-B-01-Print.pdf | AV3: 2026 09 Promo-NB Blitz 4-15 off-1mo-UWC-Awareness-B-05-Print.pdf | AW3: 2026 09 Promo-NB Blitz 4-15 off-1mo-UWC-Awareness-B-06-Print.pdf | AX3: 2026 09 Promo-NB Blitz 4-5 10 15-1mo-UWC-Awareness-V2-C-01-Print.pdf | AY3: 2026 09 Promo-NB Blitz 4-5 10 15-1mo-UWC-Awareness-V2-C-04-Print.pdf | AZ3: 2026 09 Promo-NB Blitz 4-999-1mo-UWC-Awareness-D-01-Print.pdf | BA3: 2026 09 Promo-NB Blitz 4-999-1mo-UWC-Awareness-D-02-Print.pdf | BB3: 2026 09 Promo-NB Blitz 4-999-1mo-UWC-Awareness-D-03-Print.pdf | BC3: 2026 09 Promo-NB Blitz 4-999-1mo-UWC-Awareness-D-06-Print.pdf | BD3: 2026 09 Promo-NB Blitz 4-50 off-1mo-UWC-Awareness-E-01-Print.pdf | BE3: 2026 09 Promo-NB Blitz 4-50 off-1mo-UWC-Awareness-E-03-Print.pdf | BF3: 2026 09 Promo-NB Blitz 4-50 off-1mo-UWC-Awareness-E-07-Print.pdf | BG3: 2026 09 Promo-NB Blitz 4-POR-1mo-HandheldMenu-10-10F-101-Print.pdf | BH3: 2026 09 Promo-NB Blitz 4-POR-1mo-HandheldMenu-10-10F-104-Print.pdf | BI3: 2026 09 Promo-NB Blitz 4-POR-1mo-HandheldMenu-10-10F-201-Print.pdf | BJ3: 2026 09 Promo-NB Blitz 4-999-1mo-HandheldMenu-8D-04-Print.pdf | BK3: 2026 09 Promo-NB Blitz 4-999-1mo-HandheldMenu-8D-05-Print.pdf | BL3: 2026 09 Promo-NB Blitz 4-POR-1mo-HandheldMenu-8-8F-304-Print.pdf | BM3: 2026 09 Promo-NB Blitz 4-10-3mos-HandheldMenu-A-01-Print.pdf | BN3: 2026 09 Promo-NB Blitz 4-15 off-1mo-HandheldMenu-B-01-Print.pdf | BO3: 2026 09 Promo-NB Blitz 4-15 off-1mo-HandheldMenu-B-05-Print.pdf | BP3: 2026 09 Promo-NB Blitz 4-15 off-1mo-HandheldMenu-B-06-Print.pdf | BQ3: 2026 09 Promo-NB Blitz 4-5 10 15-1mo-HandheldMenu-V2-C-01-Print.pdf | BR3: 2026 09 Promo-NB Blitz 4-5 10 15-1mo-HandheldMenu-V2-C-04-Print.pdf | BS3: 2026 09 Promo-NB Blitz 4-999-1mo-HandheldMenu-D-01-Print.pdf | BT3: 2026 09 Promo-NB Blitz 4-999-1mo-HandheldMenu-D-02-Print.pdf | BU3: 2026 09 Promo-NB Blitz 4-999-1mo-HandheldMenu-D-03-Print.pdf | BV3: 2026 09 Promo-NB Blitz 4-999-1mo-HandheldMenu-D-06-Print.pdf | BW3: 2026 09 Promo-NB Blitz 4-50 off-1mo-HandheldMenu-E-01-Print.pdf | BX3: 2026 09 Promo-NB Blitz 4-50 off-1mo-HandheldMenu-E-03-Print.pdf | BY3: 2026 09 Promo-NB Blitz 4-50 off-1mo-HandheldMenu-E-07-Print.pdf | BZ3: 2026 09 Promo-NB Blitz 4-UWC-WS-28x44-A-Print.pdf | CA3: 2026 09 Promo-NB Blitz 4-UWC-WS-28x44-B-Print.pdf | CB3: 2026 09 Promo-NB Blitz 4-UWC-WS-28x44-D-Print.pdf | CC3: 2026 09 Promo-NB Blitz 4-UWC-WS-28x44-8D-Print.pdf | CD3: 2026 09 Promo-NB Blitz 4-UWC-WS-28x44-E-Print.pdf | CE3: 2026 09 Promo-NB Blitz 4-UWC-WS-28x44-8F-Print.pdf | CF3: 2026 09 Promo-NB Blitz 4-UWC-WS-28x44-10F-Print.pdf | CG3: 2026 09 Promo-UWC-96x36 Banner-V4-A-Print.pdf | CH3: 2026 09 Promo-UWC-96x36 Banner-V4-B-Print.pdf | CI3: 2026 09 Promo-UWC-96x36 Banner-V4-C-Print.pdf | CJ3: 2026 09 Promo-UWC-96x36 Banner-V4-D-Print.pdf | CK3: 2026 09 Promo-UWC-96x36 Banner-V4-E-Print.pdf | CL3: 2026 09 Promo-UWC-96x36 Banner-V4-8F-Print.pdf | CM3: 2026 09 Promo-UWC-96x36 Banner-V4-10F-Print.pdf | CN3: 2026 09 Promo 10off 3mos Scan Cards-V2-Print | CO3: 2026 09 Promo-15 Off-1mo-ScanCard-Print | CP3: 2026 09 Promo-5-10-15-1mo-ScanCardSet-Print | CQ3: 2026 09 Promo-999-1mo-ScanCardSet-Print.pdf | CR3: 2026 09 Promo-50off-1mo-ScanCard-Print.pdf | CS3: 2026 09 All Plans PoR 1mo Scan Cards-V2-Print.pdf | CT3: 2026 09 Promo-NB Blitz 4-Collateral Guides-A-Print.pdf | CU3: 2026 09 Promo-NB Blitz 4-Collateral Guides-B-Print.pdf | CV3: 2026 09 Promo-NB Blitz 4-Collateral Guides-C-Print.pdf | CW3: 2026 09 Promo-NB Blitz 4-Collateral Guides-8D-Print.pdf | CX3: 2026 09 Promo-NB Blitz 4-Collateral Guides-D-Print.pdf | CY3: 2026 09 Promo-NB Blitz 4-Collateral Guides-E-Print.pdf | CZ3: 2026 09 Promo-NB Blitz 4-Collateral Guides-8F-Print.pdf | DA3: 2026 09 Promo-NB Blitz 4-Collateral Guides-10F-Print.pdf | DB3: Box Sticker
A4: Region | B4: CC | C4: Store # | D4: Vlookup Store # | E4: Location Name | F4: General Manager | G4: Address | H4: City | I4: State | J4: Zip Code | K4: Phone Number | L4: Promo | M4: Art Code | N4: 10F | O4: 8F | P4: A | Q4: B | R4: D | S4: E | T4: A | U4: B | V4: C | W4: D | X4: 8D | Y4: E | Z4: 8F | AA4: 10F | AB4: 10F | AC4: D | AD4: B | AE4: A | AF4: B | AG4: C | AH4: D | AI4: 8D | AJ4: E | AK4: 8F | AL4: 10F | AM4: E | AN4: 10F-101 | AO4: 10F-104 | AP4: 10F-201 | AQ4: 8D-04 | AR4: 8D-05 | AS4: 8F-304 | AT4: A01 | AU4: B01 | AV4: B05 | AW4: B06 | AX4: C01 | AY4: C04 | AZ4: D01 | BA4: D02 | BB4: D03 | BC4: D06 | BD4: E01 | BE4: E03 | BF4: E07 | BG4: 10F-101 | BH4: 10F-104 | BI4: 10F-201 | BJ4: 8D-04 | BK4: 8D-05 | BL4: 8F-304 | BM4: A01 | BN4: B01 | BO4: B05 | BP4: B06 | BQ4: C01 | BR4: C04 | BS4: D01 | BT4: D02 | BU4: D03 | BV4: D06 | BW4: E01 | BX4: E03 | BY4: E07 | BZ4: A | CA4: B | CB4: D | CC4: 8D | CD4: E | CE4: 8F | CF4: 10F | CG4: A | CH4: B | CI4: C | CJ4: D | CK4: E | CL4: 8F | CM4: 10F | CN4: A5 | CO4: B7 | CP4: C8 | CQ4: D9 | CR4: E12 | CS4: F | CT4: A | CU4: B | CV4: C | CW4: 8D | CX4: D | CY4: E | CZ4: 8F | DA4: 10F
A5: AL-Huntsville | B5: 813 | C5: 0041 | D5: 41 | E5: Hartselle | F5: MaryGrace Gilley | G5: 1206 HIGHWAY 31 NW | H5: HARTSELLE | I5: AL | J5: 35640-4421 | K5: (256) 773-7737 | L5: 50% off all plan 1 mo. | M5: E01 | AJ5: 1 | BD5: 1500 | BW5: 10 | CK5: 2 | CR5: 10 | CX5: 1 | DB5: 1
A6: AL-Huntsville | B6: 813 | C6: 0042 | D6: 42 | E6: Limestone | F6: Jamie Garrie | G6: 1321 US HIGHWAY 72 E | H6: ATHENS | I6: AL | J6: 35611-4405 | K6: (256) 233-2290 | L6: 50% off all plan 1 mo. | M6: E01 | AJ6: 1 | BD6: 1500 | BW6: 10 | CK6: 2 | CR6: 10 | CX6: 1 | DB6: 1
A7: AL-Huntsville | B7: 813 | C7: 0043 | D7: 43 | E7: Madison | F7: Klaryssa Melendrez | G7: 5509 PROMENADE POINT PKWY | H7: MADISON | I7: AL | J7: 35758-6701 | K7: (256) 895-2693 | L7: 50% off all plan 1 mo. | M7: E01 | AJ7: 1 | BD7: 1500 | BW7: 10 | CK7: 2 | CR7: 10 | CX7: 1 | DB7: 1
A8: AL-Huntsville | B8: 813 | C8: 0044 | D8: 44 | E8: Setter | F8: Stevie Wagner | G8: 627 BELTLINE RD SW | H8: DECATUR | I8: AL | J8: 35601 | K8: (256) 867-0108 | L8: 50% off all plan 1 mo. | M8: E01 | AJ8: 1 | BD8: 1500 | BW8: 10 | CK8: 2 | CR8: 10 | CX8: 1 | DB8: 1
A9: AL-Huntsville | B9: 813 | C9: 0045 | D9: 45 | E9: 9th Street | F9: Christian Rider | G9: 2240 BELTLINE RD SW | H9: DECATUR | I9: AL | J9: 35601-7001 | K9: (256) 822-2939 | L9: 50% off all plan 1 mo. | M9: E01 | AJ9: 1 | BD9: 1500 | BW9: 10 | CK9: 2 | CR9: 10 | CX9: 1 | DB9: 1
A10: AL-Huntsville | B10: 813 | C10: 0046 | D10: 46 | E10: Bassett Ave | F10: Josh Lamey | G10: 721 14TH ST SE | H10: DECATUR | I10: AL | J10: 35601-5911 | K10: (256) 822-2029 | L10: 50% off all plan 1 mo. | M10: E01 | AJ10: 1 | BD10: 1500 | BW10: 10 | CK10: 2 | CR10: 10 | CX10: 1 | DB10: 1
A11: AL-Huntsville | B11: 813 | C11: 0047 | D11: 47 | E11: Grace | F11: Justin Williams | G11: 403 US HIGHWAY 72 W | H11: ATHENS | I11: AL | J11: 35611-4207 | K11: (256) 998-5312 | L11: 50% off all plan 1 mo. | M11: E01 | AJ11: 1 | BD11: 1500 | BW11: 10 | CK11: 2 | CR11: 10 | CX11: 1 | DB11: 1
A12: AL-Huntsville | B12: 813 | C12: 0051 | D12: 51 | E12: Azalea | F12: Colby Gray | G12: 271 AZALEA DR | H12: FLORENCE | I12: AL | J12: 35630-1733 | K12: (256) 766-2726 | L12: 50% off all plan 1 mo. | M12: E01 | AJ12: 1 | BD12: 1500 | BW12: 10 | CK12: 2 | CR12: 10 | CX12: 1 | DB12: 1
A13: AL-Huntsville | B13: 813 | C13: 0052 | D13: 52 | E13: Muscle Shoals | F13: Olivia Thomsen | G13: 702 AVALON AVE | H13: MUSCLE SHOALS | I13: AL | J13: 35661-2304 | K13: (256) 389-3890 | L13: 50% off all plan 1 mo. | M13: E01 | BD13: 1500 | BW13: 10 | CD13: 1 | CK13: 2 | CR13: 10 | CX13: 1 | DB13: 1
A14: AL-Huntsville | B14: 813 | C14: 0053 | D14: 53 | E14: Cloverdale | F14: Katherine Huddleston | G14: 2914 CLOVERDALE RD | H14: FLORENCE | I14: AL | J14: 35633 | K14: (256) 712-0183 | L14: 50% off all plan 1 mo. | M14: E01 | AJ14: 1 | BD14: 1500 | BW14: 10 | CK14: 2 | CR14: 10 | CX14: 1 | DB14: 1
A15: AZ-Tucson | B15: 806 | C15: 0326 | D15: 326 | E15: Swan | F15: Sierrah Bainter | G15: 4600 E BROADWAY BLVD | H15: TUCSON | I15: AZ | J15: 85711-3512 | K15: (520) 428-0256 | L15: $9.99 all plans 1 mo. | M15: D01 | AZ15: 1500 | BS15: 10 | CB15: 1 | CJ15: 2 | CQ15: 10 | CX15: 1 | DB15: 1
A16: AZ-Tucson | B16: 806 | C16: 0327 | D16: 327 | E16: South Kolb | F16: Evelyn Conger | G16: 2409 S KOLB RD | H16: TUCSON | I16: AZ | J16: 85710 | K16: (520) 721-9290 | L16: $9.99 all plans 1 mo. | M16: D01 | AZ16: 1500 | BS16: 10 | CB16: 1 | CJ16: 2 | CQ16: 10 | CX16: 1 | DB16: 1
A17: AZ-Tucson | B17: 806 | C17: 0328 | D17: 328 | E17: Euclid | F17: Stefanie Osuna | G17: 730 E BROADWAY BLVD | H17: TUCSON | I17: AZ | J17: 85719 | K17: (520) 623-2923 | L17: $9.99 all plans 1 mo. | M17: D01 | AZ17: 1500 | BS17: 10 | CB17: 1 | CJ17: 2 | CQ17: 10 | CX17: 1 | DB17: 1
A18: AZ-Tucson | B18: 806 | C18: 0335 | D18: 335 | E18: E Grant | F18: 0 | G18: 3150 E GRANT RD | H18: TUCSON | I18: AZ | J18: 85716 | K18: (520) 881-1486 | L18: $9.99 all plans 1 mo. | M18: D01 | AZ18: 1500 | BS18: 10 | CB18: 1 | CJ18: 2 | CQ18: 10 | CX18: 1 | DB18: 1
A19: AZ-Tucson | B19: 806 | C19: 1329 | D19: 1329 | E19: Craycroft | F19: Chandrani Das | G19: 5515 E GRANT RD | H19: TUCSON | I19: AZ | J19: 85712 | K19: (520) 497-1922 | L19: $9.99 all plans 1 mo. | M19: D01 | R19: 2 | AZ19: 1500 | BS19: 10 | CJ19: 2 | CQ19: 10 | CX19: 1 | DB19: 1
A20: AZ-Tucson | B20: 806 | C20: 1331 | D20: 1331 | E20: Twin Peaks | F20: Vanna Valdez | G20: 6520 W MARANA CENTER BL | H20: TUCSON | I20: AZ | J20: 85742 | K20: (520) 335-8707 | L20: $9.99 all plans 1 mo. | M20: D01 | R20: 1 | AZ20: 1500 | BS20: 10 | CJ20: 2 | CQ20: 10 | CX20: 1 | DB20: 1
A21: AZ-Tucson | B21: 806 | C21: 2552 | D21: 2552 | E21: Tucson Mall | F21: Natalie Vazquez Martinez | G21: 4646 N ORACLE | H21: TUCSON | I21: AZ | J21: 85705 | K21: (520) 485-2620 | L21: $9.99 all plans 1 mo. | M21: D01 | R21: 1 | AZ21: 1500 | BS21: 10 | CJ21: 2 | CQ21: 10 | CX21: 1 | DB21: 1
A22: AZ-Tucson | B22: 806 | C22: 2557 | D22: 2557 | E22: Cardinal | F22: Martin Soto | G22: 2850 W VALENCIA ROAD | H22: TUCSON | I22: AZ | J22: 85746 | K22: (520) 497-1992 | L22: $9.99 all plans 1 mo. | M22: D01 | R22: 1 | AZ22: 1500 | BS22: 10 | CJ22: 2 | CQ22: 10 | CX22: 1 | DB22: 1
A23: CA-Bakersfield | B23: 830 | C23: 1016 | D23: 1016 | E23: Rosedale Hwy | F23: Adrian Vargas | G23: 11921 ROSEDALE HIGHWAY | H23: BAKERSFIELD | I23: CA | J23: 93312 | K23: (661) 230-5335 | L23: $9.99 all plans 1 mo. | M23: D01 | W23: 2 | AZ23: 1500 | BS23: 10 | CJ23: 2 | CQ23: 10 | CX23: 1 | DB23: 1
A24: CA-Bakersfield | B24: 830 | C24: 1034 | D24: 1034 | E24: Carmen | F24: Edgar Barron | G24: 1925 S BROADWAY | H24: SANTA MARIA | I24: CA | J24: 93454 | K24: (805) 621-6835 | L24: $9.99 all plans 1 mo. | M24: D01 | R24: 2 | AZ24: 1500 | BS24: 10 | CJ24: 2 | CQ24: 10 | CX24: 1 | DB24: 1
A25: CA-Bakersfield | B25: 830 | C25: 1035 | D25: 1035 | E25: Hosking | F25: Susana Ledina | G25: 1601 HOSKING AVE | H25: BAKERSFIELD | I25: CA | J25: 93307 | K25: (661) 336-9952 | L25: $9.99 all plans 1 mo. | M25: D01 | R25: 1 | AZ25: 1500 | BS25: 10 | CJ25: 2 | CQ25: 10 | CX25: 1 | DB25: 1
A26: CA-Bakersfield | B26: 830 | C26: 1038 | D26: 1038 | E26: Heath | F26: Hailey Divina | G26: 16214 STOCKDALE HWY | H26: BAKERSFIELD | I26: CA | J26: 93314 | K26: (661) 336-9403 | L26: $9.99 all plans 1 mo. | M26: D01 | R26: 2 | AZ26: 1500 | BS26: 10 | CJ26: 2 | CQ26: 10 | CX26: 1 | DB26: 1
A27: CA-Bakersfield | B27: 830 | C27: 1058 | D27: 1058 | E27: Stockdale | F27: Jorge Escobar | G27: 11417 STOCKDALE HWY | H27: BAKERSFIELD | I27: CA | J27: 93311 | K27: (661) 636-6520 | L27: $9.99 all plans 1 mo. | M27: D01 | R27: 2 | AZ27: 1500 | BS27: 10 | CJ27: 2 | CQ27: 10 | CX27: 1 | DB27: 1
A28: CA-Los Angeles | B28: 830 | C28: 1013 | D28: 1013 | E28: Hwy 138 | F28: Kayla Lopez | G28: 1822 E PALMDALE BLVD | H28: PALMDALE | I28: CA | J28: 93550 | K28: (661) 268-6424 | L28: $9.99 all plans 1 mo. | M28: D01 | W28: 2 | AZ28: 1500 | BS28: 10 | CJ28: 2 | CQ28: 10 | CX28: 1 | DB28: 1
A29: CA-Los Angeles | B29: 830 | C29: 1018 | D29: 1018 | E29: Rialto | F29: Olivia Rodriguez | G29: 127 WEST VALLEY BLVD | H29: RIALTO | I29: CA | J29: 92376 | K29: (909) 237-8099 | L29: $9.99 all plans 1 mo. | M29: D01 | R29: 2 | AZ29: 1500 | BS29: 10 | CJ29: 2 | CQ29: 10 | CX29: 1 | DB29: 1
A30: CA-Los Angeles | B30: 830 | C30: 1027 | D30: 1027 | E30: Stoneridge | F30: Zachary Ojeda | G30: 27240 EUCALYPTUS AVE | H30: MORENO VALLEY | I30: CA | J30: 92555 | K30: (951) 221-3009 | L30: $9.99 all plans 1 mo. | M30: D01 | R30: 2 | AZ30: 1500 | BS30: 10 | CJ30: 2 | CQ30: 10 | CX30: 1 | DB30: 1
A31: CA-Los Angeles | B31: 830 | C31: 1037 | D31: 1037 | E31: Varsity | F31: Anthony Fickewirth | G31: 4212 N VARSITY AVE | H31: SAN BERNARDINO | I31: CA | J31: 92407 | K31: (909) 277-6601 | L31: $9.99 all plans 1 mo. | M31: D01 | R31: 2 | AZ31: 1500 | BS31: 10 | CJ31: 2 | CQ31: 10 | CX31: 1 | DB31: 1
A32: CA-Modesto | B32: 831 | C32: 0915 | D32: 915 | E32: Merced | F32: Manuel Toro Garcia | G32: 1800 WEST OLIVE AVE | H32: MERCED | I32: CA | J32: 95348 | K32: (209) 388-9274 | L32: $9.99 all plans 1 mo. | M32: D01 | W32: 1 | AZ32: 1500 | BS32: 10 | CJ32: 2 | CQ32: 10 | CX32: 1 | DB32: 1
A33: CA-Modesto | B33: 830 | C33: 1076 | D33: 1076 | E33: Tuolumne | F33: Elicia Solis | G33: 2530 COUNTRYSIDE DR | H33: TURLOCK | I33: CA | J33: 95380 | K33: (350) 203-2119 | L33: $9.99 all plans 1 mo. | M33: D01 | R33: 2 | AZ33: 1500 | BS33: 10 | CJ33: 2 | CQ33: 10 | CX33: 1 | DB33: 1
A34: CA-San Joaquin Valley | B34: 830 | C34: 1039 | D34: 1039 | E34: Mooney Blvd | F34: Maurice Lacy | G34: 1920 S MOONEY BLVD | H34: VISALIA | I34: CA | J34: 93277 | K34: (559) 372-0454 | L34: All Plans PoR 1 mo. | M34: 10F-101 | N34: 2 | AN34: 1500 | BG34: 10 | CM34: 2 | CS34: 10 | DA34: 1 | DB34: 1
A35: CA-San Joaquin Valley | B35: 830 | C35: 1072 | D35: 1072 | E35: Reedley | F35: Francisco Villatoro | G35: 1595 W MANNING AVE | H35: REEDLEY | I35: CA | J35: 93654 | K35: (559) 554-1641 | L35: All Plans PoR 1 mo. | M35: 10F-101 | N35: 2 | AN35: 1500 | BG35: 10 | CM35: 2 | CS35: 10 | DA35: 1 | DB35: 1
A36: CA-Victor Valley | B36: 830 | C36: 1019 | D36: 1019 | E36: Happy Trails Hwy | F36: Salvador Ramirez | G36: 20440 OUTER HWY 18 | H36: APPLE VALLEY | I36: CA | J36: 92307 | K36: (760) 503-0311 | L36: $9.99 all plans 1 mo. | M36: D01 | R36: 1 | AZ36: 1500 | BS36: 10 | CJ36: 2 | CQ36: 10 | CX36: 1 | DB36: 1
A37: CA-Victor Valley | B37: 830 | C37: 1031 | D37: 1031 | E37: Jellico Ave | F37: Kenyon Mcwhorter | G37: 17112 MAIN STREET | H37: HESPERIA | I37: CA | J37: 92345 | K37: (442) 267-6146 | L37: $9.99 all plans 1 mo. | M37: D01 | R37: 2 | AZ37: 1500 | BS37: 10 | CJ37: 2 | CQ37: 10 | CX37: 1 | DB37: 1
A38: CA-Victor Valley | B38: 830 | C38: 1064 | D38: 1064 | E38: Bear Valley | F38: Natalie Craven | G38: 19389 BEAR VALLEY RD | H38: APPLE VALLEY | I38: CA | J38: 92308 | K38: (442) 855-7229 | L38: $9.99 all plans 1 mo. | M38: D01 | R38: 1 | AZ38: 1500 | BS38: 10 | CJ38: 2 | CQ38: 10 | CX38: 1 | DB38: 1
A39: CO-Colorado Springs/Pueblo/Denver | B39: 810 | C39: 0341 | D39: 341 | E39: Prospect Ave | F39: Davante Jordan | G39: 24273 E PROSPECT AVE | H39: AURORA | I39: CO | J39: 80016 | K39: (303) 928-7520 | L39: $15 off all plans 1 mo. | M39: B06 | AW39: 1500 | BP39: 10 | CA39: 1 | CH39: 2 | CO39: 10 | CU39: 1 | DB39: 1
A40: CO-Colorado Springs/Pueblo/Denver | B40: 810 | C40: 0343 | D40: 343 | E40: Woodmen | F40: Marvin Willis | G40: 5366 NEW CAR DR | H40: COLORADO SPRINGS | I40: CO | J40: 80923-8854 | K40: (719) 266-0169 | L40: $15 off all plans 1 mo. | M40: B05 | Q40: 2 | AV40: 1500 | BO40: 10 | CH40: 2 | CO40: 10 | CU40: 1 | DB40: 1
...

Sheet As Table
V1: 1500
N2: Awareness Flyers | AG2: Handheld Menus | AZ2: Mister Kiosk Stickers | BF2: Gen 2 Pegasus Kiosk Stickers | BO2: Gen 1 Pegasus Kiosk Stickers | BR2: DRB Kiosk Stickers | CA2: 28x44 Windscreens | CI2: Roadside Banners | CR2: Scancards | CX2: Collateral Guide | DD2: Box Sticker
M3: Filename | CR3: $10 for 3mos | CS3: $15 Off | CT3: $5, $10, $15 | CU3: 9.99 | CV3: 50% Off | CW3: PoR | CX3: $10 for 3mos | CY3: $15 Off | CZ3: $5, $10, $15 | DA3: 9.99 - Base $8 | DB3: 9.99 - Base $10 | DC3: 50% Off | DD3: PoR - Base $8 | DE3: PoR - Base $10
A4: Region | B4: CC | C4: Store # | D4: Vlookup Store # | E4: Location Name | F4: General Manager | G4: Address | H4: City | I4: State | J4: Zip Code | K4: Phone Number | L4: Promo | M4: Art Code | N4: 10F-101 | O4: 10F-104 | P4: 10F-201 | Q4: 8D-04 | R4: 8D-05 | S4: 8F-304 | T4: A01 | U4: B01 | V4: B05 | W4: B06 | X4: C01 | Y4: C04 | Z4: D01 | AA4: D02 | AB4: D03 | AC4: D06 | AD4: E01 | AE4: E03 | AF4: E07 | AG4: 10F-1012 | AH4: 10F-1043 | AI4: 10F-2014 | AJ4: 8D-045 | AK4: 8D-056 | AL4: 8F-3047 | AM4: A018 | AN4: B019 | AO4: B0510 | AP4: B0611 | AQ4: C0112 | AR4: C0413 | AS4: D0114 | AT4: D0215 | AU4: D0316 | AV4: D0617 | AW4: E0118 | AX4: E0319 | AY4: E0720 | AZ4: 10F | BA4: 8F | BB4: A | BC4: B | BD4: D | BE4: E | BF4: A2 | BG4: B3 | BH4: C | BI4: D4 | BJ4: 8D | BK4: E5 | BL4: 8F6 | BM4: 10F7 | BN4: G | BO4: 10F2 | BP4: D2 | BQ4: B2 | BR4: B4 | BS4: C5 | BT4: D6 | BU4: 8D7 | BV4: E8 | BW4: 8F9 | BX4: 10F10 | BY4: E11 | BZ4: G12 | CA4: A3 | CB4: B5 | CC4: D3 | CD4: 8D2 | CE4: E2 | CF4: 8F2 | CG4: 10F3 | CH4: G2 | CI4: A4 | CJ4: B6 | CK4: C7 | CL4: D8 | CM4: 8D9 | CN4: E10 | CO4: 8F11 | CP4: 10F12 | CQ4: G13 | CR4: A5 | CS4: B7 | CT4: C8 | CU4: D9 | CV4: E12 | CW4: F | CX4: A6 | CY4: B8 | CZ4: C9 | DA4: 8D10 | DB4: D11 | DC4: E13 | DD4: 8F14 | DE4: 10F | DF4: SUM | DG4: Item 2 | DH4: Item 3
A5: AL-Huntsville | B5: 813 | C5: 0041 | D5: 41 | E5: Hartselle | F5: MaryGrace Gilley | G5: 1206 HIGHWAY 31 NW | H5: HARTSELLE | I5: AL | J5: 35640-4421 | K5: (256) 773-7737 | L5: 50% off all plan 1 mo. | M5: E01 | AD5: 1500 | AW5: 10 | AZ5: =VLOOKUP(Table7[[#This Row],[Vlookup Store '#]],'Kiosk Stickers'!A$4:$H$538,2,FALSE) -> 0 | BA5: =VLOOKUP(Table7[[#This Row],[Vlookup Store '#]],'Kiosk Stickers'!A$4:$H$538,2,FALSE) -> 0 | BB5: =VLOOKUP(Table7[[#This Row],[General Manager]],'Kiosk Stickers'!C$4:$H$538,2,FALSE) -> #N/A | BC5: =VLOOKUP(Table7[[#This Row],[Address]],'Kiosk Stickers'!D$4:$H$538,2,FALSE) -> #N/A | BD5: =VLOOKUP(Table7[[#This Row],[City]],'Kiosk Stickers'!E$4:$H$538,2,FALSE) -> #N/A | BE5: =VLOOKUP(Table7[[#This Row],[State]],'Kiosk Stickers'!F$4:$H$538,2,FALSE) -> #N/A | BF5: =VLOOKUP(Table7[[#This Row],[Vlookup Store '#]],'Kiosk Stickers'!A$4:$H$538,3,FALSE) -> 0 | BO5: =VLOOKUP(Table7[[#This Row],[Vlookup Store '#]],'Kiosk Stickers'!A$4:$H$538,4,FALSE) -> 0 | BV5: =VLOOKUP(Table7[[#This Row],[Vlookup Store '#]],'Kiosk Stickers'!A$4:$H$538,5,FALSE) -> 1 | CN5: 2 | CV5: 10 | DB5: 1 | DF5: =SUM(CX5:DE5) -> 1
A6: AL-Huntsville | B6: 813 | C6: 0042 | D6: 42 | E6: Limestone | F6: Jamie Garrie | G6: 1321 US HIGHWAY 72 E | H6: ATHENS | I6: AL | J6: 35611-4405 | K6: (256) 233-2290 | L6: 50% off all plan 1 mo. | M6: E01 | AD6: 1500 | AW6: 10 | AZ6: =VLOOKUP(Table7[[#This Row],[Vlookup Store '#]],'Kiosk Stickers'!A$4:$H$538,2,FALSE) -> 0 | BF6: =VLOOKUP(Table7[[#This Row],[Vlookup Store '#]],'Kiosk Stickers'!A$4:$H$538,3,FALSE) -> 0 | BO6: =VLOOKUP(Table7[[#This Row],[Vlookup Store '#]],'Kiosk Stickers'!A$4:$H$538,4,FALSE) -> 0 | BV6: =VLOOKUP(Table7[[#This Row],[Vlookup Store '#]],'Kiosk Stickers'!A$4:$H$538,5,FALSE) -> 1 | CN6: 2 | CV6: 10 | DB6: 1 | DF6: =SUM(CX6:DE6) -> 1
A7: AL-Huntsville | B7: 813 | C7: 0043 | D7: 43 | E7: Madison | F7: Klaryssa Melendrez | G7: 5509 PROMENADE POINT PKWY | H7: MADISON | I7: AL | J7: 35758-6701 | K7: (256) 895-2693 | L7: 50% off all plan 1 mo. | M7: E01 | AD7: 1500 | AW7: 10 | AZ7: =VLOOKUP(Table7[[#This Row],[Vlookup Store '#]],'Kiosk Stickers'!A$4:$H$538,2,FALSE) -> 0 | BF7: =VLOOKUP(Table7[[#This Row],[Vlookup Store '#]],'Kiosk Stickers'!A$4:$H$538,3,FALSE) -> 0 | BO7: =VLOOKUP(Table7[[#This Row],[Vlookup Store '#]],'Kiosk Stickers'!A$4:$H$538,4,FALSE) -> 0 | BV7: =VLOOKUP(Table7[[#This Row],[Vlookup Store '#]],'Kiosk Stickers'!A$4:$H$538,5,FALSE) -> 1 | CN7: 2 | CV7: 10 | DB7: 1 | DF7: =SUM(CX7:DE7) -> 1
A8: AL-Huntsville | B8: 813 | C8: 0044 | D8: 44 | E8: Setter | F8: Stevie Wagner | G8: 627 BELTLINE RD SW | H8: DECATUR | I8: AL | J8: 35601 | K8: (256) 867-0108 | L8: 50% off all plan 1 mo. | M8: E01 | AD8: 1500 | AW8: 10 | AZ8: =VLOOKUP(Table7[[#This Row],[Vlookup Store '#]],'Kiosk Stickers'!A$4:$H$538,2,FALSE) -> 0 | BF8: =VLOOKUP(Table7[[#This Row],[Vlookup Store '#]],'Kiosk Stickers'!A$4:$H$538,3,FALSE) -> 0 | BO8: =VLOOKUP(Table7[[#This Row],[Vlookup Store '#]],'Kiosk Stickers'!A$4:$H$538,4,FALSE) -> 0 | BV8: =VLOOKUP(Table7[[#This Row],[Vlookup Store '#]],'Kiosk Stickers'!A$4:$H$538,5,FALSE) -> 1 | CN8: 2 | CV8: 10 | DB8: 1 | DF8: =SUM(CX8:DE8) -> 1
A9: AL-Huntsville | B9: 813 | C9: 0045 | D9: 45 | E9: 9th Street | F9: Christian Rider | G9: 2240 BELTLINE RD SW | H9: DECATUR | I9: AL | J9: 35601-7001 | K9: (256) 822-2939 | L9: 50% off all plan 1 mo. | M9: E01 | AD9: 1500 | AW9: 10 | AZ9: =VLOOKUP(Table7[[#This Row],[Vlookup Store '#]],'Kiosk Stickers'!A$4:$H$538,2,FALSE) -> 0 | BF9: =VLOOKUP(Table7[[#This Row],[Vlookup Store '#]],'Kiosk Stickers'!A$4:$H$538,3,FALSE) -> 0 | BO9: =VLOOKUP(Table7[[#This Row],[Vlookup Store '#]],'Kiosk Stickers'!A$4:$H$538,4,FALSE) -> 0 | BV9: =VLOOKUP(Table7[[#This Row],[Vlookup Store '#]],'Kiosk Stickers'!A$4:$H$538,5,FALSE) -> 1 | CN9: 2 | CV9: 10 | DB9: 1 | DF9: =SUM(CX9:DE9) -> 1
A10: AL-Huntsville | B10: 813 | C10: 0046 | D10: 46 | E10: Bassett Ave | F10: Josh Lamey | G10: 721 14TH ST SE | H10: DECATUR | I10: AL | J10: 35601-5911 | K10: (256) 822-2029 | L10: 50% off all plan 1 mo. | M10: E01 | AD10: 1500 | AW10: 10 | AZ10: =VLOOKUP(Table7[[#This Row],[Vlookup Store '#]],'Kiosk Stickers'!A$4:$H$538,2,FALSE) -> 0 | BF10: =VLOOKUP(Table7[[#This Row],[Vlookup Store '#]],'Kiosk Stickers'!A$4:$H$538,3,FALSE) -> 0 | BO10: =VLOOKUP(Table7[[#This Row],[Vlookup Store '#]],'Kiosk Stickers'!A$4:$H$538,4,FALSE) -> 0 | BV10: =VLOOKUP(Table7[[#This Row],[Vlookup Store '#]],'Kiosk Stickers'!A$4:$H$538,5,FALSE) -> 1 | CN10: 2 | CV10: 10 | DB10: 1 | DF10: =SUM(CX10:DE10) -> 1
A11: AL-Huntsville | B11: 813 | C11: 0047 | D11: 47 | E11: Grace | F11: Justin Williams | G11: 403 US HIGHWAY 72 W | H11: ATHENS | I11: AL | J11: 35611-4207 | K11: (256) 998-5312 | L11: 50% off all plan 1 mo. | M11: E01 | AD11: 1500 | AW11: 10 | AZ11: =VLOOKUP(Table7[[#This Row],[Vlookup Store '#]],'Kiosk Stickers'!A$4:$H$538,2,FALSE) -> 0 | BF11: =VLOOKUP(Table7[[#This Row],[Vlookup Store '#]],'Kiosk Stickers'!A$4:$H$538,3,FALSE) -> 0 | BO11: =VLOOKUP(Table7[[#This Row],[Vlookup Store '#]],'Kiosk Stickers'!A$4:$H$538,4,FALSE) -> 0 | BV11: =VLOOKUP(Table7[[#This Row],[Vlookup Store '#]],'Kiosk Stickers'!A$4:$H$538,5,FALSE) -> 1 | CN11: 2 | CV11: 10 | DB11: 1 | DF11: =SUM(CX11:DE11) -> 1
A12: AL-Huntsville | B12: 813 | C12: 0051 | D12: 51 | E12: Azalea | F12: Colby Gray | G12: 271 AZALEA DR | H12: FLORENCE | I12: AL | J12: 35630-1733 | K12: (256) 766-2726 | L12: 50% off all plan 1 mo. | M12: E01 | AD12: 1500 | AW12: 10 | AZ12: =VLOOKUP(Table7[[#This Row],[Vlookup Store '#]],'Kiosk Stickers'!A$4:$H$538,2,FALSE) -> 0 | BF12: =VLOOKUP(Table7[[#This Row],[Vlookup Store '#]],'Kiosk Stickers'!A$4:$H$538,3,FALSE) -> 0 | BO12: =VLOOKUP(Table7[[#This Row],[Vlookup Store '#]],'Kiosk Stickers'!A$4:$H$538,4,FALSE) -> 0 | BV12: =VLOOKUP(Table7[[#This Row],[Vlookup Store '#]],'Kiosk Stickers'!A$4:$H$538,5,FALSE) -> 1 | CN12: 2 | CV12: 10 | DB12: 1 | DF12: =SUM(CX12:DE12) -> 1
A13: AL-Huntsville | B13: 813 | C13: 0052 | D13: 52 | E13: Muscle Shoals | F13: Olivia Thomsen | G13: 702 AVALON AVE | H13: MUSCLE SHOALS | I13: AL | J13: 35661-2304 | K13: (256) 389-3890 | L13: 50% off all plan 1 mo. | M13: E01 | AD13: 1500 | AW13: 10 | AZ13: =VLOOKUP(Table7[[#This Row],[Vlookup Store '#]],'Kiosk Stickers'!A$4:$H$538,2,FALSE) -> 0 | BF13: =VLOOKUP(Table7[[#This Row],[Vlookup Store '#]],'Kiosk Stickers'!A$4:$H$538,3,FALSE) -> 0 | BO13: =VLOOKUP(Table7[[#This Row],[Vlookup Store '#]],'Kiosk Stickers'!A$4:$H$538,4,FALSE) -> 0 | BV13: =VLOOKUP(Table7[[#This Row],[Vlookup Store '#]],'Kiosk Stickers'!A$4:$H$538,5,FALSE) -> 0 | CE13: =VLOOKUP(Table7[[#This Row],[Vlookup Store '#]],'Kiosk Stickers'!A$4:$H$538,6,FALSE) -> 1 | CN13: 2 | CV13: 10 | DB13: 1 | DF13: =SUM(CX13:DE13) -> 1
A14: AL-Huntsville | B14: 813 | C14: 0053 | D14: 53 | E14: Cloverdale | F14: Katherine Huddleston | G14: 2914 CLOVERDALE RD | H14: FLORENCE | I14: AL | J14: 35633 | K14: (256) 712-0183 | L14: 50% off all plan 1 mo. | M14: E01 | AD14: 1500 | AW14: 10 | AZ14: =VLOOKUP(Table7[[#This Row],[Vlookup Store '#]],'Kiosk Stickers'!A$4:$H$538,2,FALSE) -> 0 | BF14: =VLOOKUP(Table7[[#This Row],[Vlookup Store '#]],'Kiosk Stickers'!A$4:$H$538,3,FALSE) -> 0 | BO14: =VLOOKUP(Table7[[#This Row],[Vlookup Store '#]],'Kiosk Stickers'!A$4:$H$538,4,FALSE) -> 0 | BV14: =VLOOKUP(Table7[[#This Row],[Vlookup Store '#]],'Kiosk Stickers'!A$4:$H$538,5,FALSE) -> 1 | CN14: 2 | CV14: 10 | DB14: 1 | DF14: =SUM(CX14:DE14) -> 1
A15: AZ-Tucson | B15: 806 | C15: 0326 | D15: 326 | E15: Swan | F15: Sierrah Bainter | G15: 4600 E BROADWAY BLVD | H15: TUCSON | I15: AZ | J15: 85711-3512 | K15: (520) 428-0256 | L15: $9.99 all plans 1 mo. | M15: D01 | Z15: 1500 | AS15: 10 | AZ15: =VLOOKUP(Table7[[#This Row],[Vlookup Store '#]],'Kiosk Stickers'!A$4:$H$538,2,FALSE) -> 0 | BF15: =VLOOKUP(Table7[[#This Row],[Vlookup Store '#]],'Kiosk Stickers'!A$4:$H$538,3,FALSE) -> 0 | BO15: =VLOOKUP(Table7[[#This Row],[Vlookup Store '#]],'Kiosk Stickers'!A$4:$H$538,4,FALSE) -> 0 | BR15: =VLOOKUP(Table7[[#This Row],[Vlookup Store '#]],'Kiosk Stickers'!A$4:$H$538,5,FALSE) -> 0 | CC15: =VLOOKUP(Table7[[#This Row],[Vlookup Store '#]],'Kiosk Stickers'!A$4:$H$538,6,FALSE) -> 1 | CL15: 2 | CU15: 10 | DB15: 1 | DF15: =SUM(CX15:DE15) -> 1
A16: AZ-Tucson | B16: 806 | C16: 0327 | D16: 327 | E16: South Kolb | F16: Evelyn Conger | G16: 2409 S KOLB RD | H16: TUCSON | I16: AZ | J16: 85710 | K16: (520) 721-9290 | L16: $9.99 all plans 1 mo. | M16: D01 | Z16: 1500 | AS16: 10 | AZ16: =VLOOKUP(Table7[[#This Row],[Vlookup Store '#]],'Kiosk Stickers'!A$4:$H$538,2,FALSE) -> 0 | BF16: =VLOOKUP(Table7[[#This Row],[Vlookup Store '#]],'Kiosk Stickers'!A$4:$H$538,3,FALSE) -> 0 | BO16: =VLOOKUP(Table7[[#This Row],[Vlookup Store '#]],'Kiosk Stickers'!A$4:$H$538,4,FALSE) -> 0 | BR16: =VLOOKUP(Table7[[#This Row],[Vlookup Store '#]],'Kiosk Stickers'!A$4:$H$538,5,FALSE) -> 0 | CC16: =VLOOKUP(Table7[[#This Row],[Vlookup Store '#]],'Kiosk Stickers'!A$4:$H$538,6,FALSE) -> 1 | CL16: 2 | CU16: 10 | DB16: 1 | DF16: =SUM(CX16:DE16) -> 1
A17: AZ-Tucson | B17: 806 | C17: 0328 | D17: 328 | E17: Euclid | F17: Stefanie Osuna | G17: 730 E BROADWAY BLVD | H17: TUCSON | I17: AZ | J17: 85719 | K17: (520) 623-2923 | L17: $9.99 all plans 1 mo. | M17: D01 | Z17: 1500 | AS17: 10 | AZ17: =VLOOKUP(Table7[[#This Row],[Vlookup Store '#]],'Kiosk Stickers'!A$4:$H$538,2,FALSE) -> 0 | BF17: =VLOOKUP(Table7[[#This Row],[Vlookup Store '#]],'Kiosk Stickers'!A$4:$H$538,3,FALSE) -> 0 | BO17: =VLOOKUP(Table7[[#This Row],[Vlookup Store '#]],'Kiosk Stickers'!A$4:$H$538,4,FALSE) -> 0 | BR17: =VLOOKUP(Table7[[#This Row],[Vlookup Store '#]],'Kiosk Stickers'!A$4:$H$538,5,FALSE) -> 0 | CC17: =VLOOKUP(Table7[[#This Row],[Vlookup Store '#]],'Kiosk Stickers'!A$4:$H$538,6,FALSE) -> 1 | CL17: 2 | CU17: 10 | DB17: 1 | DF17: =SUM(CX17:DE17) -> 1
A18: AZ-Tucson | B18: 806 | C18: 0335 | D18: 335 | E18: E Grant | F18: 0 | G18: 3150 E GRANT RD | H18: TUCSON | I18: AZ | J18: 85716 | K18: (520) 881-1486 | L18: $9.99 all plans 1 mo. | M18: D01 | Z18: 1500 | AS18: 10 | AZ18: =VLOOKUP(Table7[[#This Row],[Vlookup Store '#]],'Kiosk Stickers'!A$4:$H$538,2,FALSE) -> 0 | BF18: =VLOOKUP(Table7[[#This Row],[Vlookup Store '#]],'Kiosk Stickers'!A$4:$H$538,3,FALSE) -> 0 | BO18: =VLOOKUP(Table7[[#This Row],[Vlookup Store '#]],'Kiosk Stickers'!A$4:$H$538,4,FALSE) -> 0 | BR18: =VLOOKUP(Table7[[#This Row],[Vlookup Store '#]],'Kiosk Stickers'!A$4:$H$538,5,FALSE) -> 0 | CC18: =VLOOKUP(Table7[[#This Row],[Vlookup Store '#]],'Kiosk Stickers'!A$4:$H$538,6,FALSE) -> 1 | CL18: 2 | CU18: 10 | DB18: 1 | DF18: =SUM(CX18:DE18) -> 1
A19: AZ-Tucson | B19: 806 | C19: 1329 | D19: 1329 | E19: Craycroft | F19: Chandrani Das | G19: 5515 E GRANT RD | H19: TUCSON | I19: AZ | J19: 85712 | K19: (520) 497-1922 | L19: $9.99 all plans 1 mo. | M19: D01 | Z19: 1500 | AS19: 10 | BD19: =VLOOKUP(Table7[[#This Row],[Vlookup Store '#]],'Kiosk Stickers'!A$4:$H$538,2,FALSE) -> 2 | BF19: =VLOOKUP(Table7[[#This Row],[Vlookup Store '#]],'Kiosk Stickers'!A$4:$H$538,3,FALSE) -> 0 | BO19: =VLOOKUP(Table7[[#This Row],[Vlookup Store '#]],'Kiosk Stickers'!A$4:$H$538,4,FALSE) -> 0 | BR19: =VLOOKUP(Table7[[#This Row],[Vlookup Store '#]],'Kiosk Stickers'!A$4:$H$538,5,FALSE) -> 0 | CL19: 2 | CU19: 10 | DB19: 1 | DF19: =SUM(CX19:DE19) -> 1
A20: AZ-Tucson | B20: 806 | C20: 1331 | D20: 1331 | E20: Twin Peaks | F20: Vanna Valdez | G20: 6520 W MARANA CENTER BL | H20: TUCSON | I20: AZ | J20: 85742 | K20: (520) 335-8707 | L20: $9.99 all plans 1 mo. | M20: D01 | Z20: 1500 | AS20: 10 | BD20: 1 | CL20: 2 | CU20: 10 | DB20: 1 | DF20: =SUM(CX20:DE20) -> 1
A21: AZ-Tucson | B21: 806 | C21: 2552 | D21: 2552 | E21: Tucson Mall | F21: Natalie Vazquez Martinez | G21: 4646 N ORACLE | H21: TUCSON | I21: AZ | J21: 85705 | K21: (520) 485-2620 | L21: $9.99 all plans 1 mo. | M21: D01 | Z21: 1500 | AS21: 10 | BD21: =VLOOKUP(Table7[[#This Row],[Vlookup Store '#]],'Kiosk Stickers'!A$4:$H$538,2,FALSE) -> 1 | BF21: =VLOOKUP(Table7[[#This Row],[Vlookup Store '#]],'Kiosk Stickers'!A$4:$H$538,3,FALSE) -> 0 | BO21: =VLOOKUP(Table7[[#This Row],[Vlookup Store '#]],'Kiosk Stickers'!A$4:$H$538,4,FALSE) -> 0 | BR21: =VLOOKUP(Table7[[#This Row],[Vlookup Store '#]],'Kiosk Stickers'!A$4:$H$538,5,FALSE) -> 0 | CL21: 2 | CU21: 10 | DB21: 1 | DF21: =SUM(CX21:DE21) -> 1
A22: AZ-Tucson | B22: 806 | C22: 2557 | D22: 2557 | E22: Cardinal | F22: Martin Soto | G22: 2850 W VALENCIA ROAD | H22: TUCSON | I22: AZ | J22: 85746 | K22: (520) 497-1992 | L22: $9.99 all plans 1 mo. | M22: D01 | Z22: 1500 | AS22: 10 | BD22: =VLOOKUP(Table7[[#This Row],[Vlookup Store '#]],'Kiosk Stickers'!A$4:$H$538,2,FALSE) -> 1 | BF22: =VLOOKUP(Table7[[#This Row],[Vlookup Store '#]],'Kiosk Stickers'!A$4:$H$538,3,FALSE) -> 0 | BO22: =VLOOKUP(Table7[[#This Row],[Vlookup Store '#]],'Kiosk Stickers'!A$4:$H$538,4,FALSE) -> 0 | BR22: =VLOOKUP(Table7[[#This Row],[Vlookup Store '#]],'Kiosk Stickers'!A$4:$H$538,5,FALSE) -> 0 | CL22: 2 | CU22: 10 | DB22: 1 | DF22: =SUM(CX22:DE22) -> 1
A23: CA-Bakersfield | B23: 830 | C23: 1016 | D23: 1016 | E23: Rosedale Hwy | F23: Adrian Vargas | G23: 11921 ROSEDALE HIGHWAY | H23: BAKERSFIELD | I23: CA | J23: 93312 | K23: (661) 230-5335 | L23: $9.99 all plans 1 mo. | M23: D01 | Z23: 1500 | AS23: 10 | BD23: =VLOOKUP(Table7[[#This Row],[Vlookup Store '#]],'Kiosk Stickers'!A$4:$H$538,2,FALSE) -> 0 | BI23: =VLOOKUP(Table7[[#This Row],[Vlookup Store '#]],'Kiosk Stickers'!A$4:$H$538,3,FALSE) -> 2 | BO23: =VLOOKUP(Table7[[#This Row],[Vlookup Store '#]],'Kiosk Stickers'!A$4:$H$538,4,FALSE) -> 0 | BR23: =VLOOKUP(Table7[[#This Row],[Vlookup Store '#]],'Kiosk Stickers'!A$4:$H$538,5,FALSE) -> 0 | CL23: 2 | CU23: 10 | DB23: 1 | DF23: =SUM(CX23:DE23) -> 1
A24: CA-Bakersfield | B24: 830 | C24: 1034 | D24: 1034 | E24: Carmen | F24: Edgar Barron | G24: 1925 S BROADWAY | H24: SANTA MARIA | I24: CA | J24: 93454 | K24: (805) 621-6835 | L24: $9.99 all plans 1 mo. | M24: D01 | Z24: 1500 | AS24: 10 | BD24: =VLOOKUP(Table7[[#This Row],[Vlookup Store '#]],'Kiosk Stickers'!A$4:$H$538,2,FALSE) -> 2 | BI24: =VLOOKUP(Table7[[#This Row],[Vlookup Store '#]],'Kiosk Stickers'!A$4:$H$538,3,FALSE) -> 0 | BO24: =VLOOKUP(Table7[[#This Row],[Vlookup Store '#]],'Kiosk Stickers'!A$4:$H$538,4,FALSE) -> 0 | BR24: =VLOOKUP(Table7[[#This Row],[Vlookup Store '#]],'Kiosk Stickers'!A$4:$H$538,5,FALSE) -> 0 | CL24: 2 | CU24: 10 | DB24: 1 | DF24: =SUM(CX24:DE24) -> 1
A25: CA-Bakersfield | B25: 830 | C25: 1035 | D25: 1035 | E25: Hosking | F25: Susana Ledina | G25: 1601 HOSKING AVE | H25: BAKERSFIELD | I25: CA | J25: 93307 | K25: (661) 336-9952 | L25: $9.99 all plans 1 mo. | M25: D01 | Z25: 1500 | AS25: 10 | BD25: 1 | CL25: 2 | CU25: 10 | DB25: 1 | DF25: =SUM(CX25:DE25) -> 1
A26: CA-Bakersfield | B26: 830 | C26: 1038 | D26: 1038 | E26: Heath | F26: Hailey Divina | G26: 16214 STOCKDALE HWY | H26: BAKERSFIELD | I26: CA | J26: 93314 | K26: (661) 336-9403 | L26: $9.99 all plans 1 mo. | M26: D01 | Z26: 1500 | AS26: 10 | BD26: =VLOOKUP(Table7[[#This Row],[Vlookup Store '#]],'Kiosk Stickers'!A$4:$H$538,2,FALSE) -> 2 | BI26: =VLOOKUP(Table7[[#This Row],[Vlookup Store '#]],'Kiosk Stickers'!A$4:$H$538,3,FALSE) -> 0 | BO26: =VLOOKUP(Table7[[#This Row],[Vlookup Store '#]],'Kiosk Stickers'!A$4:$H$538,4,FALSE) -> 0 | BR26: =VLOOKUP(Table7[[#This Row],[Vlookup Store '#]],'Kiosk Stickers'!A$4:$H$538,5,FALSE) -> 0 | CL26: 2 | CU26: 10 | DB26: 1 | DF26: =SUM(CX26:DE26) -> 1
A27: CA-Bakersfield | B27: 830 | C27: 1058 | D27: 1058 | E27: Stockdale | F27: Jorge Escobar | G27: 11417 STOCKDALE HWY | H27: BAKERSFIELD | I27: CA | J27: 93311 | K27: (661) 636-6520 | L27: $9.99 all plans 1 mo. | M27: D01 | Z27: 1500 | AS27: 10 | BD27: =VLOOKUP(Table7[[#This Row],[Vlookup Store '#]],'Kiosk Stickers'!A$4:$H$538,2,FALSE) -> 2 | BI27: =VLOOKUP(Table7[[#This Row],[Vlookup Store '#]],'Kiosk Stickers'!A$4:$H$538,3,FALSE) -> 0 | BO27: =VLOOKUP(Table7[[#This Row],[Vlookup Store '#]],'Kiosk Stickers'!A$4:$H$538,4,FALSE) -> 0 | BR27: =VLOOKUP(Table7[[#This Row],[Vlookup Store '#]],'Kiosk Stickers'!A$4:$H$538,5,FALSE) -> 0 | CL27: 2 | CU27: 10 | DB27: 1 | DF27: =SUM(CX27:DE27) -> 1
A28: CA-Los Angeles | B28: 830 | C28: 1013 | D28: 1013 | E28: Hwy 138 | F28: Kayla Lopez | G28: 1822 E PALMDALE BLVD | H28: PALMDALE | I28: CA | J28: 93550 | K28: (661) 268-6424 | L28: $9.99 all plans 1 mo. | M28: D01 | Z28: 1500 | AS28: 10 | BD28: =VLOOKUP(Table7[[#This Row],[Vlookup Store '#]],'Kiosk Stickers'!A$4:$H$538,2,FALSE) -> 0 | BI28: =VLOOKUP(Table7[[#This Row],[Vlookup Store '#]],'Kiosk Stickers'!A$4:$H$538,3,FALSE) -> 2 | BO28: =VLOOKUP(Table7[[#This Row],[Vlookup Store '#]],'Kiosk Stickers'!A$4:$H$538,4,FALSE) -> 0 | BR28: =VLOOKUP(Table7[[#This Row],[Vlookup Store '#]],'Kiosk Stickers'!A$4:$H$538,5,FALSE) -> 0 | CL28: 2 | CU28: 10 | DB28: 1 | DF28: =SUM(CX28:DE28) -> 1
A29: CA-Los Angeles | B29: 830 | C29: 1018 | D29: 1018 | E29: Rialto | F29: Olivia Rodriguez | G29: 127 WEST VALLEY BLVD | H29: RIALTO | I29: CA | J29: 92376 | K29: (909) 237-8099 | L29: $9.99 all plans 1 mo. | M29: D01 | Z29: 1500 | AS29: 10 | BD29: =VLOOKUP(Table7[[#This Row],[Vlookup Store '#]],'Kiosk Stickers'!A$4:$H$538,2,FALSE) -> 2 | BI29: =VLOOKUP(Table7[[#This Row],[Vlookup Store '#]],'Kiosk Stickers'!A$4:$H$538,3,FALSE) -> 0 | BO29: =VLOOKUP(Table7[[#This Row],[Vlookup Store '#]],'Kiosk Stickers'!A$4:$H$538,4,FALSE) -> 0 | BR29: =VLOOKUP(Table7[[#This Row],[Vlookup Store '#]],'Kiosk Stickers'!A$4:$H$538,5,FALSE) -> 0 | CL29: 2 | CU29: 10 | DB29: 1 | DF29: =SUM(CX29:DE29) -> 1
A30: CA-Los Angeles | B30: 830 | C30: 1027 | D30: 1027 | E30: Stoneridge | F30: Zachary Ojeda | G30: 27240 EUCALYPTUS AVE | H30: MORENO VALLEY | I30: CA | J30: 92555 | K30: (951) 221-3009 | L30: $9.99 all plans 1 mo. | M30: D01 | Z30: 1500 | AS30: 10 | BD30: =VLOOKUP(Table7[[#This Row],[Vlookup Store '#]],'Kiosk Stickers'!A$4:$H$538,2,FALSE) -> 2 | BI30: =VLOOKUP(Table7[[#This Row],[Vlookup Store '#]],'Kiosk Stickers'!A$4:$H$538,3,FALSE) -> 0 | BO30: =VLOOKUP(Table7[[#This Row],[Vlookup Store '#]],'Kiosk Stickers'!A$4:$H$538,4,FALSE) -> 0 | BR30: =VLOOKUP(Table7[[#This Row],[Vlookup Store '#]],'Kiosk Stickers'!A$4:$H$538,5,FALSE) -> 0 | CL30: 2 | CU30: 10 | DB30: 1 | DF30: =SUM(CX30:DE30) -> 1
A31: CA-Los Angeles | B31: 830 | C31: 1037 | D31: 1037 | E31: Varsity | F31: Anthony Fickewirth | G31: 4212 N VARSITY AVE | H31: SAN BERNARDINO | I31: CA | J31: 92407 | K31: (909) 277-6601 | L31: $9.99 all plans 1 mo. | M31: D01 | Z31: 1500 | AS31: 10 | BD31: =VLOOKUP(Table7[[#This Row],[Vlookup Store '#]],'Kiosk Stickers'!A$4:$H$538,2,FALSE) -> 2 | BI31: =VLOOKUP(Table7[[#This Row],[Vlookup Store '#]],'Kiosk Stickers'!A$4:$H$538,3,FALSE) -> 0 | BO31: =VLOOKUP(Table7[[#This Row],[Vlookup Store '#]],'Kiosk Stickers'!A$4:$H$538,4,FALSE) -> 0 | BR31: =VLOOKUP(Table7[[#This Row],[Vlookup Store '#]],'Kiosk Stickers'!A$4:$H$538,5,FALSE) -> 0 | CL31: 2 | CU31: 10 | DB31: 1 | DF31: =SUM(CX31:DE31) -> 1
A32: CA-Modesto | B32: 831 | C32: 0915 | D32: 915 | E32: Merced | F32: Manuel Toro Garcia | G32: 1800 WEST OLIVE AVE | H32: MERCED | I32: CA | J32: 95348 | K32: (209) 388-9274 | L32: $9.99 all plans 1 mo. | M32: D01 | Z32: 1500 | AS32: 10 | BD32: =VLOOKUP(Table7[[#This Row],[Vlookup Store '#]],'Kiosk Stickers'!A$4:$H$538,2,FALSE) -> 0 | BI32: =VLOOKUP(Table7[[#This Row],[Vlookup Store '#]],'Kiosk Stickers'!A$4:$H$538,3,FALSE) -> 1 | BO32: =VLOOKUP(Table7[[#This Row],[Vlookup Store '#]],'Kiosk Stickers'!A$4:$H$538,4,FALSE) -> 0 | BR32: =VLOOKUP(Table7[[#This Row],[Vlookup Store '#]],'Kiosk Stickers'!A$4:$H$538,5,FALSE) -> 0 | CL32: 2 | CU32: 10 | DB32: 1 | DF32: =SUM(CX32:DE32) -> 1
A33: CA-Modesto | B33: 830 | C33: 1076 | D33: 1076 | E33: Tuolumne | F33: Elicia Solis | G33: 2530 COUNTRYSIDE DR | H33: TURLOCK | I33: CA | J33: 95380 | K33: (350) 203-2119 | L33: $9.99 all plans 1 mo. | M33: D01 | Z33: 1500 | AS33: 10 | BD33: =VLOOKUP(Table7[[#This Row],[Vlookup Store '#]],'Kiosk Stickers'!A$4:$H$538,2,FALSE) -> 2 | BF33: =VLOOKUP(Table7[[#This Row],[Vlookup Store '#]],'Kiosk Stickers'!A$4:$H$538,3,FALSE) -> 0 | BO33: =VLOOKUP(Table7[[#This Row],[Vlookup Store '#]],'Kiosk Stickers'!A$4:$H$538,4,FALSE) -> 0 | BR33: =VLOOKUP(Table7[[#This Row],[Vlookup Store '#]],'Kiosk Stickers'!A$4:$H$538,5,FALSE) -> 0 | CL33: 2 | CU33: 10 | DB33: 1 | DF33: =SUM(CX33:DE33) -> 1
A34: CA-San Joaquin Valley | B34: 830 | C34: 1039 | D34: 1039 | E34: Mooney Blvd | F34: Maurice Lacy | G34: 1920 S MOONEY BLVD | H34: VISALIA | I34: CA | J34: 93277 | K34: (559) 372-0454 | L34: All Plans PoR 1 mo. | M34: 10F-101 | N34: 1500 | AG34: 10 | AZ34: =VLOOKUP(Table7[[#This Row],[Vlookup Store '#]],'Kiosk Stickers'!A$4:$H$538,2,FALSE) -> 2 | BF34: =VLOOKUP(Table7[[#This Row],[Vlookup Store '#]],'Kiosk Stickers'!A$4:$H$538,3,FALSE) -> 0 | BO34: =VLOOKUP(Table7[[#This Row],[Vlookup Store '#]],'Kiosk Stickers'!A$4:$H$538,4,FALSE) -> 0 | BR34: =VLOOKUP(Table7[[#This Row],[Vlookup Store '#]],'Kiosk Stickers'!A$4:$H$538,5,FALSE) -> 0 | CP34: 2 | CW34: 10 | DE34: 1 | DF34: =SUM(CX34:DE34) -> 1
